Workbook
Name IQ_CH: 110000
Name IQ_CQ: 5000
Name IQ_CY: 10000
Name IQ_DAILY: 500000
Name IQ_FH: 100000
Name IQ_FQ: 500
Name IQ_FY: 1000
Name IQ_LTM: 2000
Name IQ_MONTH: 15000
Name IQ_NTM: 6000
Name IQ_WEEK: 50000
Name IQ_YTD: 3000

Sheet Model Setup
A1: MOTS(Mathematical Optimization Model for Team Scheduling)
A3: Time period(in days) for which data is incorporated in the model | B3: 20
A6: Distribution of non-FTC leads in FTC hours(local time) | B6: FTC- 8am | C6: FTC-9am | D6: FTC-10am | E6: FTC-11am | F6: FTC-12pm | G6: FTC-1pm | H6: FTC-2pm | I6: FTC-3pm | J6: FTC-4pm | K6: FTC-5pm | L6: FTC-6pm | M6: FTC-7pm | N6: FTC-8pm | O6: Total
B7: 0 | C7: 1 | D7: 2 | E7: 3 | F7: 4 | G7: 5 | H7: 6 | I7: 7 | J7: 8 | K7: 9 | L7: 10 | M7: 11 | N7: 12
B8: 0 | C8: 0 | D8: 0 | E8: 0 | F8: 0 | G8: 0 | H8: 0 | I8: 0 | J8: 0 | K8: 0 | L8: 0.3 | M8: 0.4 | N8: 0.3 | O8: =SUM(B8:N8) -> 1

Sheet Data- Refined
A1: Hourly Lead Flow By State | T1: License Profile By Team | AC1: Team Agent Totals
U2: East | W2: West | AA2: License Total By State
B3: ='Data- Extract'!CJ3 -> 5 am to 6 am | C3: ='Data- Extract'!CK3 -> 6am to 7am | D3: ='Data- Extract'!CL3 -> 7 am to 8 am | E3: ='Data- Extract'!CM3 -> 8 am to 9 am | F3: ='Data- Extract'!CN3 -> 9am to 10 am | G3: ='Data- Extract'!CO3 -> 10 am to 11 am | H3: ='Data- Extract'!CP3 -> 11 am to 12 pm | I3: ='Data- Extract'!CQ3 -> 12 pm to 1 pm | ... Q3: ='Data- Extract'!CY3 -> 8 pm to 9 pm | T3: State License | U3: Team Howard | V3: Team Smithers | W3: Elite | X3: Franchise | Y3: Market Makers | Z3: The Commissioners | AC3: Number of Agents | AD3: Team Howard | AE3: Team Smithers | AF3: Elite | AG3: Franchise | AH3: Market Makers | AI3: The Commissioners
A4: AK | B4: ='Data- Extract'!CJ5 -> 0 | C4: ='Data- Extract'!CK5 -> 0 | D4: ='Data- Extract'!CL5 -> 0 | E4: ='Data- Extract'!CM5 -> 16 | F4: ='Data- Extract'!CN5 -> 13 | G4: ='Data- Extract'!CO5 -> 10 | H4: ='Data- Extract'!CP5 -> 8 | I4: ='Data- Extract'!CQ5 -> 6 | ... Q4: ='Data- Extract'!CY5 -> 14 | T4: AK | U4: 4 | V4: 4 | W4: 2 | X4: 2 | Y4: 2 | Z4: 0 | AA4: =SUM(U4:Z4) -> 14 | AD4: 32 | AE4: 30 | AF4: 20 | AG4: 18 | AH4: 16 | AI4: 18
A5: AL | B5: ='Data- Extract'!CJ6 -> 0 | C5: ='Data- Extract'!CK6 -> 38 | D5: ='Data- Extract'!CL6 -> 66 | E5: ='Data- Extract'!CM6 -> 54 | F5: ='Data- Extract'!CN6 -> 57 | G5: ='Data- Extract'!CO6 -> 54 | H5: ='Data- Extract'!CP6 -> 34 | I5: ='Data- Extract'!CQ6 -> 24 | ... Q5: ='Data- Extract'!CY6 -> 0 | T5: AL | U5: 10 | V5: 9 | W5: 6 | X5: 2 | Y5: 4 | Z5: 6 | AA5: =SUM(U5:Z5) -> 37
A6: AR | B6: ='Data- Extract'!CJ7 -> 0 | C6: ='Data- Extract'!CK7 -> 30 | D6: ='Data- Extract'!CL7 -> 35 | E6: ='Data- Extract'!CM7 -> 46 | F6: ='Data- Extract'!CN7 -> 35 | G6: ='Data- Extract'!CO7 -> 29 | H6: ='Data- Extract'!CP7 -> 17 | I6: ='Data- Extract'!CQ7 -> 24 | ... Q6: ='Data- Extract'!CY7 -> 0 | T6: AR | U6: 5 | V6: 7 | W6: 2 | X6: 0 | Y6: 1 | Z6: 0 | AA6: =SUM(U6:Z6) -> 15 | AC6: Avg leads/MB | AJ6: =SUM(B56:Q56)/SUM(AD4:AI4)/'Model Setup'!B3 -> 14.283582
A7: AZ | B7: ='Data- Extract'!CJ8 -> 0 | C7: ='Data- Extract'!CK8 -> 0 | D7: ='Data- Extract'!CL8 -> 107 | E7: ='Data- Extract'!CM8 -> 159 | F7: ='Data- Extract'!CN8 -> 135 | G7: ='Data- Extract'!CO8 -> 101 | H7: ='Data- Extract'!CP8 -> 85 | I7: ='Data- Extract'!CQ8 -> 76 | ... Q7: ='Data- Extract'!CY8 -> 0 | T7: AZ | U7: 6 | V7: 7 | W7: 5 | X7: 8 | Y7: 3 | Z7: 4 | AA7: =SUM(U7:Z7) -> 33
A8: CA | B8: ='Data- Extract'!CJ9 -> 0 | C8: ='Data- Extract'!CK9 -> 0 | D8: ='Data- Extract'!CL9 -> 0 | E8: ='Data- Extract'!CM9 -> 526 | F8: ='Data- Extract'!CN9 -> 681 | G8: ='Data- Extract'!CO9 -> 691 | H8: ='Data- Extract'!CP9 -> 526 | I8: ='Data- Extract'!CQ9 -> 460 | ... Q8: ='Data- Extract'!CY9 -> 442 | T8: CA | U8: 28 | V8: 27 | W8: 20 | X8: 18 | Y8: 16 | Z8: 18 | AA8: =SUM(U8:Z8) -> 127
A9: CO | B9: ='Data- Extract'!CJ10 -> 0 | C9: ='Data- Extract'!CK10 -> 0 | D9: ='Data- Extract'!CL10 -> 97 | E9: ='Data- Extract'!CM10 -> 122 | F9: ='Data- Extract'!CN10 -> 121 | G9: ='Data- Extract'!CO10 -> 109 | H9: ='Data- Extract'!CP10 -> 71 | I9: ='Data- Extract'!CQ10 -> 54 | ... Q9: ='Data- Extract'!CY10 -> 0 | T9: CO | U9: 11 | V9: 11 | W9: 10 | X9: 10 | Y9: 6 | Z9: 5 | AA9: =SUM(U9:Z9) -> 53
A10: CT | B10: ='Data- Extract'!CJ11 -> 0 | C10: ='Data- Extract'!CK11 -> 67 | D10: ='Data- Extract'!CL11 -> 101 | E10: ='Data- Extract'!CM11 -> 99 | F10: ='Data- Extract'!CN11 -> 94 | G10: ='Data- Extract'!CO11 -> 69 | H10: ='Data- Extract'!CP11 -> 48 | I10: ='Data- Extract'!CQ11 -> 30 | ... Q10: ='Data- Extract'!CY11 -> 0 | T10: CT | U10: 13 | V10: 15 | W10: 9 | X10: 7 | Y10: 6 | Z10: 7 | AA10: =SUM(U10:Z10) -> 57
A11: DC | B11: ='Data- Extract'!CJ12 -> 1 | C11: ='Data- Extract'!CK12 -> 12 | D11: ='Data- Extract'!CL12 -> 10 | E11: ='Data- Extract'!CM12 -> 18 | F11: ='Data- Extract'!CN12 -> 20 | G11: ='Data- Extract'!CO12 -> 12 | H11: ='Data- Extract'!CP12 -> 7 | I11: ='Data- Extract'!CQ12 -> 8 | ... Q11: ='Data- Extract'!CY12 -> 0 | T11: DC | U11: 6 | V11: 4 | W11: 1 | X11: 1 | Y11: 3 | Z11: 1 | AA11: =SUM(U11:Z11) -> 16
A12: DE | B12: ='Data- Extract'!CJ13 -> 8 | C12: ='Data- Extract'!CK13 -> 18 | D12: ='Data- Extract'!CL13 -> 17 | E12: ='Data- Extract'!CM13 -> 11 | F12: ='Data- Extract'!CN13 -> 15 | G12: ='Data- Extract'!CO13 -> 12 | H12: ='Data- Extract'!CP13 -> 11 | I12: ='Data- Extract'!CQ13 -> 10 | ... Q12: ='Data- Extract'!CY13 -> 0 | T12: DE | U12: 6 | V12: 8 | W12: 1 | X12: 5 | Y12: 1 | Z12: 4 | AA12: =SUM(U12:Z12) -> 25
A13: FL | B13: ='Data- Extract'!CJ14 -> 78 | C13: ='Data- Extract'!CK14 -> 262 | D13: ='Data- Extract'!CL14 -> 250 | E13: ='Data- Extract'!CM14 -> 242 | F13: ='Data- Extract'!CN14 -> 230 | G13: ='Data- Extract'!CO14 -> 185 | H13: ='Data- Extract'!CP14 -> 202 | I13: ='Data- Extract'!CQ14 -> 170 | ... Q13: ='Data- Extract'!CY14 -> 0 | T13: FL | U13: 20 | V13: 17 | W13: 8 | X13: 8 | Y13: 10 | Z13: 9 | AA13: =SUM(U13:Z13) -> 72
A14: GA | B14: ='Data- Extract'!CJ15 -> 35 | C14: ='Data- Extract'!CK15 -> 130 | D14: ='Data- Extract'!CL15 -> 128 | E14: ='Data- Extract'!CM15 -> 146 | F14: ='Data- Extract'!CN15 -> 143 | G14: ='Data- Extract'!CO15 -> 119 | H14: ='Data- Extract'!CP15 -> 99 | I14: ='Data- Extract'!CQ15 -> 76 | ... Q14: ='Data- Extract'!CY15 -> 0 | T14: GA | U14: 14 | V14: 9 | W14: 8 | X14: 10 | Y14: 6 | Z14: 2 | AA14: =SUM(U14:Z14) -> 49
A15: HI | B15: ='Data- Extract'!CJ16 -> 0 | C15: ='Data- Extract'!CK16 -> 19 | D15: ='Data- Extract'!CL16 -> 14 | E15: ='Data- Extract'!CM16 -> 9 | F15: ='Data- Extract'!CN16 -> 12 | G15: ='Data- Extract'!CO16 -> 14 | H15: ='Data- Extract'!CP16 -> 12 | I15: ='Data- Extract'!CQ16 -> 12 | ... Q15: ='Data- Extract'!CY16 -> 0 | T15: HI | U15: 7 | V15: 9 | W15: 5 | X15: 3 | Y15: 2 | Z15: 0 | AA15: =SUM(U15:Z15) -> 26
A16: IA | B16: ='Data- Extract'!CJ17 -> 0 | C16: ='Data- Extract'!CK17 -> 18 | D16: ='Data- Extract'!CL17 -> 23 | E16: ='Data- Extract'!CM17 -> 12 | F16: ='Data- Extract'!CN17 -> 20 | G16: ='Data- Extract'!CO17 -> 16 | H16: ='Data- Extract'!CP17 -> 12 | I16: ='Data- Extract'!CQ17 -> 15 | ... Q16: ='Data- Extract'!CY17 -> 0 | T16: IA | U16: 4 | V16: 2 | W16: 3 | X16: 4 | Y16: 4 | Z16: 1 | AA16: =SUM(U16:Z16) -> 18
A17: ID | B17: ='Data- Extract'!CJ18 -> 0 | C17: ='Data- Extract'!CK18 -> 0 | D17: ='Data- Extract'!CL18 -> 24 | E17: ='Data- Extract'!CM18 -> 21 | F17: ='Data- Extract'!CN18 -> 23 | G17: ='Data- Extract'!CO18 -> 22 | H17: ='Data- Extract'!CP18 -> 19 | I17: ='Data- Extract'!CQ18 -> 14 | ... Q17: ='Data- Extract'!CY18 -> 0 | T17: ID | U17: 4 | V17: 5 | W17: 1 | X17: 1 | Y17: 0 | Z17: 0 | AA17: =SUM(U17:Z17) -> 11
A18: IL | B18: ='Data- Extract'!CJ19 -> 0 | C18: ='Data- Extract'!CK19 -> 0 | D18: ='Data- Extract'!CL19 -> 135 | E18: ='Data- Extract'!CM19 -> 139 | F18: ='Data- Extract'!CN19 -> 119 | G18: ='Data- Extract'!CO19 -> 107 | H18: ='Data- Extract'!CP19 -> 109 | I18: ='Data- Extract'!CQ19 -> 95 | ... Q18: ='Data- Extract'!CY19 -> 0 | T18: IL | U18: 14 | V18: 12 | W18: 9 | X18: 8 | Y18: 8 | Z18: 7 | AA18: =SUM(U18:Z18) -> 58
... A55: WY | B55: ='Data- Extract'!CJ56 -> 0 | C55: ='Data- Extract'!CK56 -> 0 | D55: ='Data- Extract'!CL56 -> 18 | E55: ='Data- Extract'!CM56 -> 17 | F55: ='Data- Extract'!CN56 -> 16 | G55: ='Data- Extract'!CO56 -> 12 | H55: ='Data- Extract'!CP56 -> 10 | I55: ='Data- Extract'!CQ56 -> 11 | ... Q55: ='Data- Extract'!CY56 -> 0 | T55: WY | U55: 4 | V55: 5 | W55: 0 | X55: 1 | Y55: 1 | Z55: 1 | AA55: =SUM(U55:Z55) -> 12
A56: Totals | B56: =SUM(B4:B55) -> 521 | C56: =SUM(C4:C55) -> 2347 | D56: =SUM(D4:D55) -> 3383 | E56: =SUM(E4:E55) -> 4363 | F56: =SUM(F4:F55) -> 4392 | G56: =SUM(G4:G55) -> 4019 | H56: =SUM(H4:H55) -> 3180 | I56: =SUM(I4:I55) -> 2636 | ... Q56: =SUM(Q4:Q55) -> 592 | T56: Totals | U56: =SUM(U4:U55) -> 456 | V56: =SUM(V4:V55) -> 456 | W56: =SUM(W4:W55) -> 299 | X56: =SUM(X4:X55) -> 259 | Y56: =SUM(Y4:Y55) -> 222 | Z56: =SUM(Z4:Z55) -> 208

Sheet Optimization Model
B1: Optimized Matrix | I1: Approx. Leads / MB
C3: East | E3: West | L3: # of teams in Total (Constraint)
C4: Team Howard | D4: Team Smithers | E4: Elite | F4: Franchise | G4: Market Makers | H4: The Commissioners | S4: Average of leads/license/hr (minimized value) | T4: =AVERAGE(C31:P82) -> 4.7893466
B5: ='Data- Refined'!B3 -> 5 am to 6 am | C5: 1 | D5: 0 | E5: 0 | F5: 0 | G5: 0 | H5: 0 | I5: =' Metrics Calculation'!L13 -> 0.8140625 | L5: =SUM(C5:D5) -> 1 | M5: >= | N5: 1
B6: ='Data- Refined'!C3 -> 6am to 7am | C6: 0 | D6: 1 | E6: 0 | F6: 0 | G6: 0 | H6: 0 | I6: =' Metrics Calculation'!L14 -> 3.9116667 | L6: =SUM(C6:D6) -> 1 | M6: >= | N6: 1 | S6: Timeslots with no Coverage | T6: =COUNTIF(U31:AJ82,"=NA") -> 10
B7: ='Data- Refined'!D3 -> 7 am to 8 am | C7: 1 | D7: 0 | E7: 0 | F7: 0 | G7: 0 | H7: 0 | I7: =' Metrics Calculation'!L15 -> 5.2859375 | L7: =SUM(C7:H7) -> 1 | M7: >= | N7: 1
B8: ='Data- Refined'!E3 -> 8 am to 9 am | C8: 0 | D8: 1 | E8: 0 | F8: 0 | G8: 0 | H8: 1 | I8: =' Metrics Calculation'!L16 -> 4.5447917 | L8: =SUM(C8:H8) -> 2 | M8: >= | N8: 1
B9: ='Data- Refined'!F3 -> 9am to 10 am | C9: 1 | D9: 0 | E9: 0 | F9: 1 | G9: 0 | H9: 0 | I9: =' Metrics Calculation'!L17 -> 4.392 | L9: =SUM(C9:H9) -> 2 | M9: >= | N9: 1
B10: ='Data- Refined'!G3 -> 10 am to 11 am | C10: 0 | D10: 1 | E10: 0 | F10: 1 | G10: 0 | H10: 0 | I10: =' Metrics Calculation'!L18 -> 4.1864583 | L10: =SUM(C10:H10) -> 2 | M10: >= | N10: 1
B11: ='Data- Refined'!H3 -> 11 am to 12 pm | C11: 0 | D11: 0 | E11: 1 | F11: 0 | G11: 1 | H11: 0 | I11: =' Metrics Calculation'!L19 -> 4.4166667 | L11: =SUM(C11:H11) -> 2 | M11: >= | N11: 1
B12: ='Data- Refined'!I3 -> 12 pm to 1 pm | C12: 0 | D12: 0 | E12: 0 | F12: 0 | G12: 1 | H12: 1 | I12: =' Metrics Calculation'!L20 -> 3.8764706 | L12: =SUM(C12:H12) -> 2 | M12: >= | N12: 1
B13: ='Data- Refined'!J3 -> 1pm to 2 pm | C13: 1 | D13: 0 | E13: 0 | F13: 0 | G13: 0 | H13: 0 | I13: =' Metrics Calculation'!L21 -> 3.7484375 | L13: =SUM(C13:H13) -> 1 | M13: >= | N13: 1
B14: ='Data- Refined'!K3 -> 2 pm to 3 pm | C14: 0 | D14: 1 | E14: 0 | F14: 0 | G14: 0 | H14: 0 | I14: =' Metrics Calculation'!L22 -> 3.0883333 | L14: =SUM(C14:H14) -> 1 | M14: >= | N14: 1
B15: ='Data- Refined'!L3 -> 3 pm to 4 pm | C15: 0 | D15: 0 | E15: 0 | F15: 1 | G15: 1 | H15: 0 | I15: =' Metrics Calculation'!L23 -> 2.7632353 | L15: =SUM(C15:H15) -> 2 | M15: >= | N15: 1
B16: ='Data- Refined'!M3 -> 4 pm to 5 pm | C16: 0 | D16: 0 | E16: 1 | F16: 0 | G16: 0 | H16: 0 | I16: =' Metrics Calculation'!L24 -> 4.8475 | L16: =SUM(C16:H16) -> 1 | M16: >= | N16: 1
B17: ='Data- Refined'!N3 -> 5 pm to 6 pm | C17: 0 | D17: 0 | E17: 1 | F17: 0 | G17: 1 | H17: 0 | I17: =' Metrics Calculation'!L25 -> 2.6916667 | L17: =SUM(C17:H17) -> 2 | M17: >= | N17: 1
B18: ='Data- Refined'!O3 -> 6 pm to 7 pm | C18: 0 | D18: 0 | E18: 1 | F18: 1 | G18: 0 | H18: 0 | I18: =' Metrics Calculation'!L26 -> 2.0276316 | L18: =SUM(C18:H18) -> 2 | M18: >= | N18: 1
B19: ='Data- Refined'!P3 -> 7 pm to 8 pm | C19: 0 | D19: 0 | E19: 0 | F19: 0 | G19: 0 | H19: 1 | I19: =' Metrics Calculation'!L27 -> 3.6055556 | L19: =SUM(C19:H19) -> 1 | M19: >= | N19: 1
B20: ='Data- Refined'!Q3 -> 8 pm to 9 pm | C20: 0 | D20: 0 | E20: 0 | F20: 0 | G20: 0 | H20: 1 | I20: =' Metrics Calculation'!L28 -> 1.6444444 | L20: =SUM(C20:H20) -> 1 | M20: >= | N20: 1
B21: # of Leads/MB/day | C21: =' Metrics Calculation'!B5 -> 14.240438 | D21: =' Metrics Calculation'!C5 -> 15.73125 | E21: =' Metrics Calculation'!D5 -> 13.983465 | F21: =' Metrics Calculation'!E5 -> 13.369325 | G21: =' Metrics Calculation'!F5 -> 13.748039 | H21: =' Metrics Calculation'!G5 -> 13.671262
B24: # of hours/team (Constraint) | C24: =SUM('Optimization Model'!C5:C18) -> 4 | D24: =SUM('Optimization Model'!D5:D18) -> 4 | E24: =SUM('Optimization Model'!E7:E20) -> 4 | F24: =SUM('Optimization Model'!F7:F20) -> 4 | G24: =SUM('Optimization Model'!G7:G20) -> 4 | H24: =SUM('Optimization Model'!H7:H20) -> 4
C25: <= | D25: <= | E25: <= | F25: <= | G25: <= | H25: <=
C26: 4 | D26: 4 | E26: 4 | F26: 4 | G26: 4 | H26: 4
B29: Minimization Matrix | T29: Availability Matrix (NA => No Coverage)
C30: ='Data- Refined'!B3 -> 5 am to 6 am | D30: ='Data- Refined'!C3 -> 6am to 7am | E30: ='Data- Refined'!D3 -> 7 am to 8 am | F30: ='Data- Refined'!E3 -> 8 am to 9 am | G30: ='Data- Refined'!F3 -> 9am to 10 am | H30: ='Data- Refined'!G3 -> 10 am to 11 am | I30: ='Data- Refined'!H3 -> 11 am to 12 pm | J30: ='Data- Refined'!I3 -> 12 pm to 1 pm | ... R30: ='Data- Refined'!Q3 -> 8 pm to 9 pm | U30: =C30 -> 5 am to 6 am | V30: =D30 -> 6am to 7am | W30: =E30 -> 7 am to 8 am | X30: =F30 -> 8 am to 9 am | Y30: =G30 -> 9am to 10 am | Z30: =H30 -> 10 am to 11 am | AA30: =I30 -> 11 am to 12 pm | AB30: =J30 -> 12 pm to 1 pm | ... AJ30: =R30 -> 8 pm to 9 pm
B31: AK | C31: =IFERROR('Data- Refined'!$B4/'Support Calculation'!$Q4,'Data- Refined'!$B4) -> 0 | D31: =IFERROR('Data- Refined'!$C4/'Support Calculation'!$Z4,'Data- Refined'!$C4) -> 0 | E31: =IFERROR('Data- Refined'!$D4/'Support Calculation'!$AI4,'Data- Refined'!$D4) -> 0 | F31: =IFERROR('Data- Refined'!$E4/'Support Calculation'!$AR4,'Data- Refined'!$E4) -> 4 | G31: =IFERROR('Data- Refined'!$F4/'Support Calculation'!$BA4,'Data- Refined'!$F4) -> 2.1666667 | H31: =IFERROR('Data- Refined'!$G4/'Support Calculation'!$BJ4,'Data- Refined'!$G4) -> 1.6666667 | I31: =IFERROR('Data- Refined'!$H4/'Support Calculation'!$BS4,'Data- Refined'!$H4) -> 2 | J31: =IFERROR('Data- Refined'!$I4/'Support Calculation'!$CB4,'Data- Refined'!$I4) -> 3 | K31: =IFERROR('Data- Refined'!$J4/'Support Calculation'!$CK4,'Data- Refined'!$J4) -> 2 | L31: =IFERROR('Data- Refined'!$K4/'Support Calculation'!$CT4,'Data- Refined'!$K4) -> 1.5 | M31: =IFERROR('Data- Refined'!$L4/'Support Calculation'!$DC4,'Data- Refined'!$L4) -> 1.25 | N31: =IFERROR('Data- Refined'!$M4/'Support Calculation'!$DL4,'Data- Refined'!$M4) -> 2 | O31: =IFERROR('Data- Refined'!$N4/'Support Calculation'!$DU4,'Data- Refined'!$N4) -> 1 | P31: =IFERROR('Data- Refined'!$O4/'Support Calculation'!$ED4,'Data- Refined'!$O4) -> 3.75 | Q31: =IFERROR('Data- Refined'!$P4/'Support Calculation'!EM4,'Data- Refined'!$P4) -> 20 | R31: =IFERROR('Data- Refined'!$Q4/'Support Calculation'!EV4,'Data- Refined'!$Q4) -> 14 | T31: AK | U31: =IFERROR('Data- Refined'!$B4/'Support Calculation'!$Q4,IF('Data- Refined'!$B4=0,0,"NA")) -> 0 | V31: =IFERROR('Data- Refined'!$C4/'Support Calculation'!$Z4,IF('Data- Refined'!$C4=0,0,"NA")) -> 0 | W31: =IFERROR('Data- Refined'!$D4/'Support Calculation'!$AI4,IF('Data- Refined'!$D4=0,0,"NA")) -> 0 | X31: =IFERROR('Data- Refined'!$E4/'Support Calculation'!$AR4,IF('Data- Refined'!$E4=0,0,"NA")) -> 4 | Y31: =IFERROR('Data- Refined'!$F4/'Support Calculation'!$BA4,IF('Data- Refined'!$F4=0,0,"NA")) -> 2.1666667 | Z31: =IFERROR('Data- Refined'!$G4/'Support Calculation'!$BJ4,IF('Data- Refined'!$G4=0,0,"NA")) -> 1.6666667 | AA31: =IFERROR('Data- Refined'!$H4/'Support Calculation'!$BS4,IF('Data- Refined'!$H4=0,0,"NA")) -> 2 | AB31: =IFERROR('Data- Refined'!$I4/'Support Calculation'!$CB4,IF('Data- Refined'!$I4=0,0,"NA")) -> 3 | AC31: =IFERROR('Data- Refined'!$J4/'Support Calculation'!$CK4,IF('Data- Refined'!$J4=0,0,"NA")) -> 2 | AD31: =IFERROR('Data- Refined'!$K4/'Support Calculation'!$CT4,IF('Data- Refined'!$K4=0,0,"NA")) -> 1.5 | AE31: =IFERROR('Data- Refined'!$L4/'Support Calculation'!$DC4,IF('Data- Refined'!$L4=0,0,"NA")) -> 1.25 | AF31: =IFERROR('Data- Refined'!$M4/'Support Calculation'!$DL4,IF('Data- Refined'!$M4=0,0,"NA")) -> 2 | AG31: =IFERROR('Data- Refined'!$N4/'Support Calculation'!$DU4,IF('Data- Refined'!$N4=0,0,"NA")) -> 1 | AH31: =IFERROR('Data- Refined'!$O4/'Support Calculation'!$ED4,IF('Data- Refined'!$O4=0,0,"NA")) -> 3.75 | AI31: =IFERROR('Data- Refined'!$P4/'Support Calculation'!EM4,IF('Data- Refined'!$P4=0,0,"NA")) -> NA | AJ31: =IFERROR('Data- Refined'!$Q4/'Support Calculation'!EV4,IF('Data- Refined'!$Q4=0,0,"NA")) -> NA
B32: AL | C32: =IFERROR('Data- Refined'!$B5/'Support Calculation'!$Q5,'Data- Refined'!$B5) -> 0 | D32: =IFERROR('Data- Refined'!$C5/'Support Calculation'!$Z5,'Data- Refined'!$C5) -> 4.2222222 | E32: =IFERROR('Data- Refined'!$D5/'Support Calculation'!$AI5,'Data- Refined'!$D5) -> 6.6 | F32: =IFERROR('Data- Refined'!$E5/'Support Calculation'!$AR5,'Data- Refined'!$E5) -> 3.6 | G32: =IFERROR('Data- Refined'!$F5/'Support Calculation'!$BA5,'Data- Refined'!$F5) -> 4.75 | H32: =IFERROR('Data- Refined'!$G5/'Support Calculation'!$BJ5,'Data- Refined'!$G5) -> 4.9090909 | I32: =IFERROR('Data- Refined'!$H5/'Support Calculation'!$BS5,'Data- Refined'!$H5) -> 3.4 | J32: =IFERROR('Data- Refined'!$I5/'Support Calculation'!$CB5,'Data- Refined'!$I5) -> 2.4 | K32: =IFERROR('Data- Refined'!$J5/'Support Calculation'!$CK5,'Data- Refined'!$J5) -> 3.5 | L32: =IFERROR('Data- Refined'!$K5/'Support Calculation'!$CT5,'Data- Refined'!$K5) -> 2.6666667 | M32: =IFERROR('Data- Refined'!$L5/'Support Calculation'!$DC5,'Data- Refined'!$L5) -> 1.8333333 | N32: =IFERROR('Data- Refined'!$M5/'Support Calculation'!$DL5,'Data- Refined'!$M5) -> 3.5 | O32: =IFERROR('Data- Refined'!$N5/'Support Calculation'!$DU5,'Data- Refined'!$N5) -> 2.5 | P32: =IFERROR('Data- Refined'!$O5/'Support Calculation'!$ED5,'Data- Refined'!$O5) -> 2.375 | Q32: =IFERROR('Data- Refined'!$P5/'Support Calculation'!EM5,'Data- Refined'!$P5) -> 0 | R32: =IFERROR('Data- Refined'!$Q5/'Support Calculation'!EV5,'Data- Refined'!$Q5) -> 0 | T32: AL | U32: =IFERROR('Data- Refined'!$B5/'Support Calculation'!$Q5,IF('Data- Refined'!$B5=0,0,"NA")) -> 0 | V32: =IFERROR('Data- Refined'!$C5/'Support Calculation'!$Z5,IF('Data- Refined'!$C5=0,0,"NA")) -> 4.2222222 | W32: =IFERROR('Data- Refined'!$D5/'Support Calculation'!$AI5,IF('Data- Refined'!$D5=0,0,"NA")) -> 6.6 | X32: =IFERROR('Data- Refined'!$E5/'Support Calculation'!$AR5,IF('Data- Refined'!$E5=0,0,"NA")) -> 3.6 | Y32: =IFERROR('Data- Refined'!$F5/'Support Calculation'!$BA5,IF('Data- Refined'!$F5=0,0,"NA")) -> 4.75 | Z32: =IFERROR('Data- Refined'!$G5/'Support Calculation'!$BJ5,IF('Data- Refined'!$G5=0,0,"NA")) -> 4.9090909 | AA32: =IFERROR('Data- Refined'!$H5/'Support Calculation'!$BS5,IF('Data- Refined'!$H5=0,0,"NA")) -> 3.4 | AB32: =IFERROR('Data- Refined'!$I5/'Support Calculation'!$CB5,IF('Data- Refined'!$I5=0,0,"NA")) -> 2.4 | AC32: =IFERROR('Data- Refined'!$J5/'Support Calculation'!$CK5,IF('Data- Refined'!$J5=0,0,"NA")) -> 3.5 | AD32: =IFERROR('Data- Refined'!$K5/'Support Calculation'!$CT5,IF('Data- Refined'!$K5=0,0,"NA")) -> 2.6666667 | AE32: =IFERROR('Data- Refined'!$L5/'Support Calculation'!$DC5,IF('Data- Refined'!$L5=0,0,"NA")) -> 1.8333333 | AF32: =IFERROR('Data- Refined'!$M5/'Support Calculation'!$DL5,IF('Data- Refined'!$M5=0,0,"NA")) -> 3.5 | AG32: =IFERROR('Data- Refined'!$N5/'Support Calculation'!$DU5,IF('Data- Refined'!$N5=0,0,"NA")) -> 2.5 | AH32: =IFERROR('Data- Refined'!$O5/'Support Calculation'!$ED5,IF('Data- Refined'!$O5=0,0,"NA")) -> 2.375 | AI32: =IFERROR('Data- Refined'!$P5/'Support Calculation'!EM5,IF('Data- Refined'!$P5=0,0,"NA")) -> 0 | AJ32: =IFERROR('Data- Refined'!$Q5/'Support Calculation'!EV5,IF('Data- Refined'!$Q5=0,0,"NA")) -> 0
B33: AR | C33: =IFERROR('Data- Refined'!$B6/'Support Calculation'!$Q6,'Data- Refined'!$B6) -> 0 | D33: =IFERROR('Data- Refined'!$C6/'Support Calculation'!$Z6,'Data- Refined'!$C6) -> 4.2857143 | E33: =IFERROR('Data- Refined'!$D6/'Support Calculation'!$AI6,'Data- Refined'!$D6) -> 7 | F33: =IFERROR('Data- Refined'!$E6/'Support Calculation'!$AR6,'Data- Refined'!$E6) -> 6.5714286 | G33: =IFERROR('Data- Refined'!$F6/'Support Calculation'!$BA6,'Data- Refined'!$F6) -> 7 | H33: =IFERROR('Data- Refined'!$G6/'Support Calculation'!$BJ6,'Data- Refined'!$G6) -> 4.1428571 | I33: =IFERROR('Data- Refined'!$H6/'Support Calculation'!$BS6,'Data- Refined'!$H6) -> 5.6666667 | J33: =IFERROR('Data- Refined'!$I6/'Support Calculation'!$CB6,'Data- Refined'!$I6) -> 24 | K33: =IFERROR('Data- Refined'!$J6/'Support Calculation'!$CK6,'Data- Refined'!$J6) -> 3.4 | L33: =IFERROR('Data- Refined'!$K6/'Support Calculation'!$CT6,'Data- Refined'!$K6) -> 2.4285714 | M33: =IFERROR('Data- Refined'!$L6/'Support Calculation'!$DC6,'Data- Refined'!$L6) -> 10 | N33: =IFERROR('Data- Refined'!$M6/'Support Calculation'!$DL6,'Data- Refined'!$M6) -> 8 | O33: =IFERROR('Data- Refined'!$N6/'Support Calculation'!$DU6,'Data- Refined'!$N6) -> 5 | P33: =IFERROR('Data- Refined'!$O6/'Support Calculation'!$ED6,'Data- Refined'!$O6) -> 7.5 | Q33: =IFERROR('Data- Refined'!$P6/'Support Calculation'!EM6,'Data- Refined'!$P6) -> 0 | R33: =IFERROR('Data- Refined'!$Q6/'Support Calculation'!EV6,'Data- Refined'!$Q6) -> 0 | T33: AR | U33: =IFERROR('Data- Refined'!$B6/'Support Calculation'!$Q6,IF('Data- Refined'!$B6=0,0,"NA")) -> 0 | V33: =IFERROR('Data- Refined'!$C6/'Support Calculation'!$Z6,IF('Data- Refined'!$C6=0,0,"NA")) -> 4.2857143 | W33: =IFERROR('Data- Refined'!$D6/'Support Calculation'!$AI6,IF('Data- Refined'!$D6=0,0,"NA")) -> 7 | X33: =IFERROR('Data- Refined'!$E6/'Support Calculation'!$AR6,IF('Data- Refined'!$E6=0,0,"NA")) -> 6.5714286 | Y33: =IFERROR('Data- Refined'!$F6/'Support Calculation'!$BA6,IF('Data- Refined'!$F6=0,0,"NA")) -> 7 | Z33: =IFERROR('Data- Refined'!$G6/'Support Calculation'!$BJ6,IF('Data- Refined'!$G6=0,0,"NA")) -> 4.1428571 | AA33: =IFERROR('Data- Refined'!$H6/'Support Calculation'!$BS6,IF('Data- Refined'!$H6=0,0,"NA")) -> 5.6666667 | AB33: =IFERROR('Data- Refined'!$I6/'Support Calculation'!$CB6,IF('Data- Refined'!$I6=0,0,"NA")) -> 24 | AC33: =IFERROR('Data- Refined'!$J6/'Support Calculation'!$CK6,IF('Data- Refined'!$J6=0,0,"NA")) -> 3.4 | AD33: =IFERROR('Data- Refined'!$K6/'Support Calculation'!$CT6,IF('Data- Refined'!$K6=0,0,"NA")) -> 2.4285714 | AE33: =IFERROR('Data- Refined'!$L6/'Support Calculation'!$DC6,IF('Data- Refined'!$L6=0,0,"NA")) -> 10 | AF33: =IFERROR('Data- Refined'!$M6/'Support Calculation'!$DL6,IF('Data- Refined'!$M6=0,0,"NA")) -> 8 | AG33: =IFERROR('Data- Refined'!$N6/'Support Calculation'!$DU6,IF('Data- Refined'!$N6=0,0,"NA")) -> 5 | AH33: =IFERROR('Data- Refined'!$O6/'Support Calculation'!$ED6,IF('Data- Refined'!$O6=0,0,"NA")) -> 7.5 | AI33: =IFERROR('Data- Refined'!$P6/'Support Calculation'!EM6,IF('Data- Refined'!$P6=0,0,"NA")) -> 0 | AJ33: =IFERROR('Data- Refined'!$Q6/'Support Calculation'!EV6,IF('Data- Refined'!$Q6=0,0,"NA")) -> 0
B34: AZ | C34: =IFERROR('Data- Refined'!$B7/'Support Calculation'!$Q7,'Data- Refined'!$B7) -> 0 | D34: =IFERROR('Data- Refined'!$C7/'Support Calculation'!$Z7,'Data- Refined'!$C7) -> 0 | E34: =IFERROR('Data- Refined'!$D7/'Support Calculation'!$AI7,'Data- Refined'!$D7) -> 17.833333 | F34: =IFERROR('Data- Refined'!$E7/'Support Calculation'!$AR7,'Data- Refined'!$E7) -> 14.454545 | G34: =IFERROR('Data- Refined'!$F7/'Support Calculation'!$BA7,'Data- Refined'!$F7) -> 9.6428571 | H34: =IFERROR('Data- Refined'!$G7/'Support Calculation'!$BJ7,'Data- Refined'!$G7) -> 6.7333333 | I34: =IFERROR('Data- Refined'!$H7/'Support Calculation'!$BS7,'Data- Refined'!$H7) -> 10.625 | J34: =IFERROR('Data- Refined'!$I7/'Support Calculation'!$CB7,'Data- Refined'!$I7) -> 10.857143 | K34: =IFERROR('Data- Refined'!$J7/'Support Calculation'!$CK7,'Data- Refined'!$J7) -> 12.333333 | L34: =IFERROR('Data- Refined'!$K7/'Support Calculation'!$CT7,'Data- Refined'!$K7) -> 9.4285714 | M34: =IFERROR('Data- Refined'!$L7/'Support Calculation'!$DC7,'Data- Refined'!$L7) -> 4.1818182 | N34: =IFERROR('Data- Refined'!$M7/'Support Calculation'!$DL7,'Data- Refined'!$M7) -> 5.4 | O34: =IFERROR('Data- Refined'!$N7/'Support Calculation'!$DU7,'Data- Refined'!$N7) -> 9.125 | P34: =IFERROR('Data- Refined'!$O7/'Support Calculation'!$ED7,'Data- Refined'!$O7) -> 6.5384615 | Q34: =IFERROR('Data- Refined'!$P7/'Support Calculation'!EM7,'Data- Refined'!$P7) -> 16.5 | R34: =IFERROR('Data- Refined'!$Q7/'Support Calculation'!EV7,'Data- Refined'!$Q7) -> 0 | T34: AZ | U34: =IFERROR('Data- Refined'!$B7/'Support Calculation'!$Q7,IF('Data- Refined'!$B7=0,0,"NA")) -> 0 | V34: =IFERROR('Data- Refined'!$C7/'Support Calculation'!$Z7,IF('Data- Refined'!$C7=0,0,"NA")) -> 0 | W34: =IFERROR('Data- Refined'!$D7/'Support Calculation'!$AI7,IF('Data- Refined'!$D7=0,0,"NA")) -> 17.833333 | X34: =IFERROR('Data- Refined'!$E7/'Support Calculation'!$AR7,IF('Data- Refined'!$E7=0,0,"NA")) -> 14.454545 | Y34: =IFERROR('Data- Refined'!$F7/'Support Calculation'!$BA7,IF('Data- Refined'!$F7=0,0,"NA")) -> 9.6428571 | Z34: =IFERROR('Data- Refined'!$G7/'Support Calculation'!$BJ7,IF('Data- Refined'!$G7=0,0,"NA")) -> 6.7333333 | AA34: =IFERROR('Data- Refined'!$H7/'Support Calculation'!$BS7,IF('Data- Refined'!$H7=0,0,"NA")) -> 10.625 | AB34: =IFERROR('Data- Refined'!$I7/'Support Calculation'!$CB7,IF('Data- Refined'!$I7=0,0,"NA")) -> 10.857143 | AC34: =IFERROR('Data- Refined'!$J7/'Support Calculation'!$CK7,IF('Data- Refined'!$J7=0,0,"NA")) -> 12.333333 | AD34: =IFERROR('Data- Refined'!$K7/'Support Calculation'!$CT7,IF('Data- Refined'!$K7=0,0,"NA")) -> 9.4285714 | AE34: =IFERROR('Data- Refined'!$L7/'Support Calculation'!$DC7,IF('Data- Refined'!$L7=0,0,"NA")) -> 4.1818182 | AF34: =IFERROR('Data- Refined'!$M7/'Support Calculation'!$DL7,IF('Data- Refined'!$M7=0,0,"NA")) -> 5.4 | AG34: =IFERROR('Data- Refined'!$N7/'Support Calculation'!$DU7,IF('Data- Refined'!$N7=0,0,"NA")) -> 9.125 | AH34: =IFERROR('Data- Refined'!$O7/'Support Calculation'!$ED7,IF('Data- Refined'!$O7=0,0,"NA")) -> 6.5384615 | AI34: =IFERROR('Data- Refined'!$P7/'Support Calculation'!EM7,IF('Data- Refined'!$P7=0,0,"NA")) -> 16.5 | AJ34: =IFERROR('Data- Refined'!$Q7/'Support Calculation'!EV7,IF('Data- Refined'!$Q7=0,0,"NA")) -> 0
B35: CA | C35: =IFERROR('Data- Refined'!$B8/'Support Calculation'!$Q8,'Data- Refined'!$B8) -> 0 | D35: =IFERROR('Data- Refined'!$C8/'Support Calculation'!$Z8,'Data- Refined'!$C8) -> 0 | E35: =IFERROR('Data- Refined'!$D8/'Support Calculation'!$AI8,'Data- Refined'!$D8) -> 0 | F35: =IFERROR('Data- Refined'!$E8/'Support Calculation'!$AR8,'Data- Refined'!$E8) -> 11.688889 | G35: =IFERROR('Data- Refined'!$F8/'Support Calculation'!$BA8,'Data- Refined'!$F8) -> 14.804348 | H35: =IFERROR('Data- Refined'!$G8/'Support Calculation'!$BJ8,'Data- Refined'!$G8) -> 15.355556 | I35: =IFERROR('Data- Refined'!$H8/'Support Calculation'!$BS8,'Data- Refined'!$H8) -> 14.611111 | J35: =IFERROR('Data- Refined'!$I8/'Support Calculation'!$CB8,'Data- Refined'!$I8) -> 13.529412 | K35: =IFERROR('Data- Refined'!$J8/'Support Calculation'!$CK8,'Data- Refined'!$J8) -> 14.928571 | L35: =IFERROR('Data- Refined'!$K8/'Support Calculation'!$CT8,'Data- Refined'!$K8) -> 11.851852 | M35: =IFERROR('Data- Refined'!$L8/'Support Calculation'!$DC8,'Data- Refined'!$L8) -> 8.7647059 | N35: =IFERROR('Data- Refined'!$M8/'Support Calculation'!$DL8,'Data- Refined'!$M8) -> 14.6 | O35: =IFERROR('Data- Refined'!$N8/'Support Calculation'!$DU8,'Data- Refined'!$N8) -> 4.9722222 | P35: =IFERROR('Data- Refined'!$O8/'Support Calculation'!$ED8,'Data- Refined'!$O8) -> 13.394737 | Q35: =IFERROR('Data- Refined'!$P8/'Support Calculation'!EM8,'Data- Refined'!$P8) -> 33.111111 | R35: =IFERROR('Data- Refined'!$Q8/'Support Calculation'!EV8,'Data- Refined'!$Q8) -> 24.555556 | T35: CA | U35: =IFERROR('Data- Refined'!$B8/'Support Calculation'!$Q8,IF('Data- Refined'!$B8=0,0,"NA")) -> 0 | V35: =IFERROR('Data- Refined'!$C8/'Support Calculation'!$Z8,IF('Data- Refined'!$C8=0,0,"NA")) -> 0 | W35: =IFERROR('Data- Refined'!$D8/'Support Calculation'!$AI8,IF('Data- Refined'!$D8=0,0,"NA")) -> 0 | X35: =IFERROR('Data- Refined'!$E8/'Support Calculation'!$AR8,IF('Data- Refined'!$E8=0,0,"NA")) -> 11.688889 | Y35: =IFERROR('Data- Refined'!$F8/'Support Calculation'!$BA8,IF('Data- Refined'!$F8=0,0,"NA")) -> 14.804348 | Z35: =IFERROR('Data- Refined'!$G8/'Support Calculation'!$BJ8,IF('Data- Refined'!$G8=0,0,"NA")) -> 15.355556 | AA35: =IFERROR('Data- Refined'!$H8/'Support Calculation'!$BS8,IF('Data- Refined'!$H8=0,0,"NA")) -> 14.611111 | AB35: =IFERROR('Data- Refined'!$I8/'Support Calculation'!$CB8,IF('Data- Refined'!$I8=0,0,"NA")) -> 13.529412 | AC35: =IFERROR('Data- Refined'!$J8/'Support Calculation'!$CK8,IF('Data- Refined'!$J8=0,0,"NA")) -> 14.928571 | AD35: =IFERROR('Data- Refined'!$K8/'Support Calculation'!$CT8,IF('Data- Refined'!$K8=0,0,"NA")) -> 11.851852 | AE35: =IFERROR('Data- Refined'!$L8/'Support Calculation'!$DC8,IF('Data- Refined'!$L8=0,0,"NA")) -> 8.7647059 | AF35: =IFERROR('Data- Refined'!$M8/'Support Calculation'!$DL8,IF('Data- Refined'!$M8=0,0,"NA")) -> 14.6 | AG35: =IFERROR('Data- Refined'!$N8/'Support Calculation'!$DU8,IF('Data- Refined'!$N8=0,0,"NA")) -> 4.9722222 | AH35: =IFERROR('Data- Refined'!$O8/'Support Calculation'!$ED8,IF('Data- Refined'!$O8=0,0,"NA")) -> 13.394737 | AI35: =IFERROR('Data- Refined'!$P8/'Support Calculation'!EM8,IF('Data- Refined'!$P8=0,0,"NA")) -> 33.111111 | AJ35: =IFERROR('Data- Refined'!$Q8/'Support Calculation'!EV8,IF('Data- Refined'!$Q8=0,0,"NA")) -> 24.555556
B36: CO | C36: =IFERROR('Data- Refined'!$B9/'Support Calculation'!$Q9,'Data- Refined'!$B9) -> 0 | D36: =IFERROR('Data- Refined'!$C9/'Support Calculation'!$Z9,'Data- Refined'!$C9) -> 0 | E36: =IFERROR('Data- Refined'!$D9/'Support Calculation'!$AI9,'Data- Refined'!$D9) -> 8.8181818 | F36: =IFERROR('Data- Refined'!$E9/'Support Calculation'!$AR9,'Data- Refined'!$E9) -> 7.625 | G36: =IFERROR('Data- Refined'!$F9/'Support Calculation'!$BA9,'Data- Refined'!$F9) -> 5.7619048 | H36: =IFERROR('Data- Refined'!$G9/'Support Calculation'!$BJ9,'Data- Refined'!$G9) -> 5.1904762 | I36: =IFERROR('Data- Refined'!$H9/'Support Calculation'!$BS9,'Data- Refined'!$H9) -> 4.4375 | J36: =IFERROR('Data- Refined'!$I9/'Support Calculation'!$CB9,'Data- Refined'!$I9) -> 4.9090909 | K36: =IFERROR('Data- Refined'!$J9/'Support Calculation'!$CK9,'Data- Refined'!$J9) -> 4.9090909 | L36: =IFERROR('Data- Refined'!$K9/'Support Calculation'!$CT9,'Data- Refined'!$K9) -> 4.9090909 | M36: =IFERROR('Data- Refined'!$L9/'Support Calculation'!$DC9,'Data- Refined'!$L9) -> 1.625 | N36: =IFERROR('Data- Refined'!$M9/'Support Calculation'!$DL9,'Data- Refined'!$M9) -> 3 | O36: =IFERROR('Data- Refined'!$N9/'Support Calculation'!$DU9,'Data- Refined'!$N9) -> 3.3125 | P36: =IFERROR('Data- Refined'!$O9/'Support Calculation'!$ED9,'Data- Refined'!$O9) -> 2.85 | Q36: =IFERROR('Data- Refined'!$P9/'Support Calculation'!EM9,'Data- Refined'!$P9) -> 9.2 | R36: =IFERROR('Data- Refined'!$Q9/'Support Calculation'!EV9,'Data- Refined'!$Q9) -> 0 | T36: CO | U36: =IFERROR('Data- Refined'!$B9/'Support Calculation'!$Q9,IF('Data- Refined'!$B9=0,0,"NA")) -> 0 | V36: =IFERROR('Data- Refined'!$C9/'Support Calculation'!$Z9,IF('Data- Refined'!$C9=0,0,"NA")) -> 0 | W36: =IFERROR('Data- Refined'!$D9/'Support Calculation'!$AI9,IF('Data- Refined'!$D9=0,0,"NA")) -> 8.8181818 | X36: =IFERROR('Data- Refined'!$E9/'Support Calculation'!$AR9,IF('Data- Refined'!$E9=0,0,"NA")) -> 7.625 | Y36: =IFERROR('Data- Refined'!$F9/'Support Calculation'!$BA9,IF('Data- Refined'!$F9=0,0,"NA")) -> 5.7619048 | Z36: =IFERROR('Data- Refined'!$G9/'Support Calculation'!$BJ9,IF('Data- Refined'!$G9=0,0,"NA")) -> 5.1904762 | AA36: =IFERROR('Data- Refined'!$H9/'Support Calculation'!$BS9,IF('Data- Refined'!$H9=0,0,"NA")) -> 4.4375 | AB36: =IFERROR('Data- Refined'!$I9/'Support Calculation'!$CB9,IF('Data- Refined'!$I9=0,0,"NA")) -> 4.9090909 | AC36: =IFERROR('Data- Refined'!$J9/'Support Calculation'!$CK9,IF('Data- Refined'!$J9=0,0,"NA")) -> 4.9090909 | AD36: =IFERROR('Data- Refined'!$K9/'Support Calculation'!$CT9,IF('Data- Refined'!$K9=0,0,"NA")) -> 4.9090909 | AE36: =IFERROR('Data- Refined'!$L9/'Support Calculation'!$DC9,IF('Data- Refined'!$L9=0,0,"NA")) -> 1.625 | AF36: =IFERROR('Data- Refined'!$M9/'Support Calculation'!$DL9,IF('Data- Refined'!$M9=0,0,"NA")) -> 3 | AG36: =IFERROR('Data- Refined'!$N9/'Support Calculation'!$DU9,IF('Data- Refined'!$N9=0,0,"NA")) -> 3.3125 | AH36: =IFERROR('Data- Refined'!$O9/'Support Calculation'!$ED9,IF('Data- Refined'!$O9=0,0,"NA")) -> 2.85 | AI36: =IFERROR('Data- Refined'!$P9/'Support Calculation'!EM9,IF('Data- Refined'!$P9=0,0,"NA")) -> 9.2 | AJ36: =IFERROR('Data- Refined'!$Q9/'Support Calculation'!EV9,IF('Data- Refined'!$Q9=0,0,"NA")) -> 0
B37: CT | C37: =IFERROR('Data- Refined'!$B10/'Support Calculation'!$Q10,'Data- Refined'!$B10) -> 0 | D37: =IFERROR('Data- Refined'!$C10/'Support Calculation'!$Z10,'Data- Refined'!$C10) -> 4.4666667 | E37: =IFERROR('Data- Refined'!$D10/'Support Calculation'!$AI10,'Data- Refined'!$D10) -> 7.7692308 | F37: =IFERROR('Data- Refined'!$E10/'Support Calculation'!$AR10,'Data- Refined'!$E10) -> 4.5 | G37: =IFERROR('Data- Refined'!$F10/'Support Calculation'!$BA10,'Data- Refined'!$F10) -> 4.7 | H37: =IFERROR('Data- Refined'!$G10/'Support Calculation'!$BJ10,'Data- Refined'!$G10) -> 3.1363636 | I37: =IFERROR('Data- Refined'!$H10/'Support Calculation'!$BS10,'Data- Refined'!$H10) -> 3.2 | J37: =IFERROR('Data- Refined'!$I10/'Support Calculation'!$CB10,'Data- Refined'!$I10) -> 2.3076923 | K37: =IFERROR('Data- Refined'!$J10/'Support Calculation'!$CK10,'Data- Refined'!$J10) -> 2 | L37: =IFERROR('Data- Refined'!$K10/'Support Calculation'!$CT10,'Data- Refined'!$K10) -> 1.3333333 | M37: =IFERROR('Data- Refined'!$L10/'Support Calculation'!$DC10,'Data- Refined'!$L10) -> 2.0769231 | N37: =IFERROR('Data- Refined'!$M10/'Support Calculation'!$DL10,'Data- Refined'!$M10) -> 3.4444444 | O37: =IFERROR('Data- Refined'!$N10/'Support Calculation'!$DU10,'Data- Refined'!$N10) -> 2.7333333 | P37: =IFERROR('Data- Refined'!$O10/'Support Calculation'!$ED10,'Data- Refined'!$O10) -> 1.875 | Q37: =IFERROR('Data- Refined'!$P10/'Support Calculation'!EM10,'Data- Refined'!$P10) -> 0 | R37: =IFERROR('Data- Refined'!$Q10/'Support Calculation'!EV10,'Data- Refined'!$Q10) -> 0 | T37: CT | U37: =IFERROR('Data- Refined'!$B10/'Support Calculation'!$Q10,IF('Data- Refined'!$B10=0,0,"NA")) -> 0 | V37: =IFERROR('Data- Refined'!$C10/'Support Calculation'!$Z10,IF('Data- Refined'!$C10=0,0,"NA")) -> 4.4666667 | W37: =IFERROR('Data- Refined'!$D10/'Support Calculation'!$AI10,IF('Data- Refined'!$D10=0,0,"NA")) -> 7.7692308 | X37: =IFERROR('Data- Refined'!$E10/'Support Calculation'!$AR10,IF('Data- Refined'!$E10=0,0,"NA")) -> 4.5 | Y37: =IFERROR('Data- Refined'!$F10/'Support Calculation'!$BA10,IF('Data- Refined'!$F10=0,0,"NA")) -> 4.7 | Z37: =IFERROR('Data- Refined'!$G10/'Support Calculation'!$BJ10,IF('Data- Refined'!$G10=0,0,"NA")) -> 3.1363636 | AA37: =IFERROR('Data- Refined'!$H10/'Support Calculation'!$BS10,IF('Data- Refined'!$H10=0,0,"NA")) -> 3.2 | AB37: =IFERROR('Data- Refined'!$I10/'Support Calculation'!$CB10,IF('Data- Refined'!$I10=0,0,"NA")) -> 2.3076923 | AC37: =IFERROR('Data- Refined'!$J10/'Support Calculation'!$CK10,IF('Data- Refined'!$J10=0,0,"NA")) -> 2 | AD37: =IFERROR('Data- Refined'!$K10/'Support Calculation'!$CT10,IF('Data- Refined'!$K10=0,0,"NA")) -> 1.3333333 | AE37: =IFERROR('Data- Refined'!$L10/'Support Calculation'!$DC10,IF('Data- Refined'!$L10=0,0,"NA")) -> 2.0769231 | AF37: =IFERROR('Data- Refined'!$M10/'Support Calculation'!$DL10,IF('Data- Refined'!$M10=0,0,"NA")) -> 3.4444444 | AG37: =IFERROR('Data- Refined'!$N10/'Support Calculation'!$DU10,IF('Data- Refined'!$N10=0,0,"NA")) -> 2.7333333 | AH37: =IFERROR('Data- Refined'!$O10/'Support Calculation'!$ED10,IF('Data- Refined'!$O10=0,0,"NA")) -> 1.875 | AI37: =IFERROR('Data- Refined'!$P10/'Support Calculation'!EM10,IF('Data- Refined'!$P10=0,0,"NA")) -> 0 | AJ37: =IFERROR('Data- Refined'!$Q10/'Support Calculation'!EV10,IF('Data- Refined'!$Q10=0,0,"NA")) -> 0
B38: DC | C38: =IFERROR('Data- Refined'!$B11/'Support Calculation'!$Q11,'Data- Refined'!$B11) -> 0.16666667 | D38: =IFERROR('Data- Refined'!$C11/'Support Calculation'!$Z11,'Data- Refined'!$C11) -> 3 | E38: =IFERROR('Data- Refined'!$D11/'Support Calculation'!$AI11,'Data- Refined'!$D11) -> 1.6666667 | F38: =IFERROR('Data- Refined'!$E11/'Support Calculation'!$AR11,'Data- Refined'!$E11) -> 3.6 | G38: =IFERROR('Data- Refined'!$F11/'Support Calculation'!$BA11,'Data- Refined'!$F11) -> 2.8571429 | H38: =IFERROR('Data- Refined'!$G11/'Support Calculation'!$BJ11,'Data- Refined'!$G11) -> 2.4 | I38: =IFERROR('Data- Refined'!$H11/'Support Calculation'!$BS11,'Data- Refined'!$H11) -> 1.75 | J38: =IFERROR('Data- Refined'!$I11/'Support Calculation'!$CB11,'Data- Refined'!$I11) -> 2 | K38: =IFERROR('Data- Refined'!$J11/'Support Calculation'!$CK11,'Data- Refined'!$J11) -> 1.6666667 | L38: =IFERROR('Data- Refined'!$K11/'Support Calculation'!$CT11,'Data- Refined'!$K11) -> 1.75 | M38: =IFERROR('Data- Refined'!$L11/'Support Calculation'!$DC11,'Data- Refined'!$L11) -> 1.25 | N38: =IFERROR('Data- Refined'!$M11/'Support Calculation'!$DL11,'Data- Refined'!$M11) -> 2 | O38: =IFERROR('Data- Refined'!$N11/'Support Calculation'!$DU11,'Data- Refined'!$N11) -> 1 | P38: =IFERROR('Data- Refined'!$O11/'Support Calculation'!$ED11,'Data- Refined'!$O11) -> 0 | Q38: =IFERROR('Data- Refined'!$P11/'Support Calculation'!EM11,'Data- Refined'!$P11) -> 0 | R38: =IFERROR('Data- Refined'!$Q11/'Support Calculation'!EV11,'Data- Refined'!$Q11) -> 0 | T38: DC | U38: =IFERROR('Data- Refined'!$B11/'Support Calculation'!$Q11,IF('Data- Refined'!$B11=0,0,"NA")) -> 0.16666667 | V38: =IFERROR('Data- Refined'!$C11/'Support Calculation'!$Z11,IF('Data- Refined'!$C11=0,0,"NA")) -> 3 | W38: =IFERROR('Data- Refined'!$D11/'Support Calculation'!$AI11,IF('Data- Refined'!$D11=0,0,"NA")) -> 1.6666667 | X38: =IFERROR('Data- Refined'!$E11/'Support Calculation'!$AR11,IF('Data- Refined'!$E11=0,0,"NA")) -> 3.6 | Y38: =IFERROR('Data- Refined'!$F11/'Support Calculation'!$BA11,IF('Data- Refined'!$F11=0,0,"NA")) -> 2.8571429 | Z38: =IFERROR('Data- Refined'!$G11/'Support Calculation'!$BJ11,IF('Data- Refined'!$G11=0,0,"NA")) -> 2.4 | AA38: =IFERROR('Data- Refined'!$H11/'Support Calculation'!$BS11,IF('Data- Refined'!$H11=0,0,"NA")) -> 1.75 | AB38: =IFERROR('Data- Refined'!$I11/'Support Calculation'!$CB11,IF('Data- Refined'!$I11=0,0,"NA")) -> 2 | AC38: =IFERROR('Data- Refined'!$J11/'Support Calculation'!$CK11,IF('Data- Refined'!$J11=0,0,"NA")) -> 1.6666667 | AD38: =IFERROR('Data- Refined'!$K11/'Support Calculation'!$CT11,IF('Data- Refined'!$K11=0,0,"NA")) -> 1.75 | AE38: =IFERROR('Data- Refined'!$L11/'Support Calculation'!$DC11,IF('Data- Refined'!$L11=0,0,"NA")) -> 1.25 | AF38: =IFERROR('Data- Refined'!$M11/'Support Calculation'!$DL11,IF('Data- Refined'!$M11=0,0,"NA")) -> 2 | AG38: =IFERROR('Data- Refined'!$N11/'Support Calculation'!$DU11,IF('Data- Refined'!$N11=0,0,"NA")) -> 1 | AH38: =IFERROR('Data- Refined'!$O11/'Support Calculation'!$ED11,IF('Data- Refined'!$O11=0,0,"NA")) -> 0 | AI38: =IFERROR('Data- Refined'!$P11/'Support Calculation'!EM11,IF('Data- Refined'!$P11=0,0,"NA")) -> 0 | AJ38: =IFERROR('Data- Refined'!$Q11/'Support Calculation'!EV11,IF('Data- Refined'!$Q11=0,0,"NA")) -> 0
B39: DE | C39: =IFERROR('Data- Refined'!$B12/'Support Calculation'!$Q12,'Data- Refined'!$B12) -> 1.3333333 | D39: =IFERROR('Data- Refined'!$C12/'Support Calculation'!$Z12,'Data- Refined'!$C12) -> 2.25 | E39: =IFERROR('Data- Refined'!$D12/'Support Calculation'!$AI12,'Data- Refined'!$D12) -> 2.8333333 | F39: =IFERROR('Data- Refined'!$E12/'Support Calculation'!$AR12,'Data- Refined'!$E12) -> 0.91666667 | G39: =IFERROR('Data- Refined'!$F12/'Support Calculation'!$BA12,'Data- Refined'!$F12) -> 1.3636364 | H39: =IFERROR('Data- Refined'!$G12/'Support Calculation'!$BJ12,'Data- Refined'!$G12) -> 0.92307692 | I39: =IFERROR('Data- Refined'!$H12/'Support Calculation'!$BS12,'Data- Refined'!$H12) -> 5.5 | J39: =IFERROR('Data- Refined'!$I12/'Support Calculation'!$CB12,'Data- Refined'!$I12) -> 2 | K39: =IFERROR('Data- Refined'!$J12/'Support Calculation'!$CK12,'Data- Refined'!$J12) -> 1.3333333 | L39: =IFERROR('Data- Refined'!$K12/'Support Calculation'!$CT12,'Data- Refined'!$K12) -> 0.75 | M39: =IFERROR('Data- Refined'!$L12/'Support Calculation'!$DC12,'Data- Refined'!$L12) -> 1.3333333 | N39: =IFERROR('Data- Refined'!$M12/'Support Calculation'!$DL12,'Data- Refined'!$M12) -> 9 | O39: =IFERROR('Data- Refined'!$N12/'Support Calculation'!$DU12,'Data- Refined'!$N12) -> 5 | P39: =IFERROR('Data- Refined'!$O12/'Support Calculation'!$ED12,'Data- Refined'!$O12) -> 0 | Q39: =IFERROR('Data- Refined'!$P12/'Support Calculation'!EM12,'Data- Refined'!$P12) -> 0 | R39: =IFERROR('Data- Refined'!$Q12/'Support Calculation'!EV12,'Data- Refined'!$Q12) -> 0 | T39: DE | U39: =IFERROR('Data- Refined'!$B12/'Support Calculation'!$Q12,IF('Data- Refined'!$B12=0,0,"NA")) -> 1.3333333 | V39: =IFERROR('Data- Refined'!$C12/'Support Calculation'!$Z12,IF('Data- Refined'!$C12=0,0,"NA")) -> 2.25 | W39: =IFERROR('Data- Refined'!$D12/'Support Calculation'!$AI12,IF('Data- Refined'!$D12=0,0,"NA")) -> 2.8333333 | X39: =IFERROR('Data- Refined'!$E12/'Support Calculation'!$AR12,IF('Data- Refined'!$E12=0,0,"NA")) -> 0.91666667 | Y39: =IFERROR('Data- Refined'!$F12/'Support Calculation'!$BA12,IF('Data- Refined'!$F12=0,0,"NA")) -> 1.3636364 | Z39: =IFERROR('Data- Refined'!$G12/'Support Calculation'!$BJ12,IF('Data- Refined'!$G12=0,0,"NA")) -> 0.92307692 | AA39: =IFERROR('Data- Refined'!$H12/'Support Calculation'!$BS12,IF('Data- Refined'!$H12=0,0,"NA")) -> 5.5 | AB39: =IFERROR('Data- Refined'!$I12/'Support Calculation'!$CB12,IF('Data- Refined'!$I12=0,0,"NA")) -> 2 | AC39: =IFERROR('Data- Refined'!$J12/'Support Calculation'!$CK12,IF('Data- Refined'!$J12=0,0,"NA")) -> 1.3333333 | AD39: =IFERROR('Data- Refined'!$K12/'Support Calculation'!$CT12,IF('Data- Refined'!$K12=0,0,"NA")) -> 0.75 | AE39: =IFERROR('Data- Refined'!$L12/'Support Calculation'!$DC12,IF('Data- Refined'!$L12=0,0,"NA")) -> 1.3333333 | AF39: =IFERROR('Data- Refined'!$M12/'Support Calculation'!$DL12,IF('Data- Refined'!$M12=0,0,"NA")) -> 9 | AG39: =IFERROR('Data- Refined'!$N12/'Support Calculation'!$DU12,IF('Data- Refined'!$N12=0,0,"NA")) -> 5 | AH39: =IFERROR('Data- Refined'!$O12/'Support Calculation'!$ED12,IF('Data- Refined'!$O12=0,0,"NA")) -> 0 | AI39: =IFERROR('Data- Refined'!$P12/'Support Calculation'!EM12,IF('Data- Refined'!$P12=0,0,"NA")) -> 0 | AJ39: =IFERROR('Data- Refined'!$Q12/'Support Calculation'!EV12,IF('Data- Refined'!$Q12=0,0,"NA")) -> 0
B40: FL | C40: =IFERROR('Data- Refined'!$B13/'Support Calculation'!$Q13,'Data- Refined'!$B13) -> 3.9 | D40: =IFERROR('Data- Refined'!$C13/'Support Calculation'!$Z13,'Data- Refined'!$C13) -> 15.411765 | E40: =IFERROR('Data- Refined'!$D13/'Support Calculation'!$AI13,'Data- Refined'!$D13) -> 12.5 | F40: =IFERROR('Data- Refined'!$E13/'Support Calculation'!$AR13,'Data- Refined'!$E13) -> 9.3076923 | G40: =IFERROR('Data- Refined'!$F13/'Support Calculation'!$BA13,'Data- Refined'!$F13) -> 8.2142857 | H40: =IFERROR('Data- Refined'!$G13/'Support Calculation'!$BJ13,'Data- Refined'!$G13) -> 7.4 | I40: =IFERROR('Data- Refined'!$H13/'Support Calculation'!$BS13,'Data- Refined'!$H13) -> 11.222222 | J40: =IFERROR('Data- Refined'!$I13/'Support Calculation'!$CB13,'Data- Refined'!$I13) -> 8.9473684 | K40: =IFERROR('Data- Refined'!$J13/'Support Calculation'!$CK13,'Data- Refined'!$J13) -> 7.4 | L40: =IFERROR('Data- Refined'!$K13/'Support Calculation'!$CT13,'Data- Refined'!$K13) -> 6.7647059 | M40: =IFERROR('Data- Refined'!$L13/'Support Calculation'!$DC13,'Data- Refined'!$L13) -> 8.1111111 | N40: =IFERROR('Data- Refined'!$M13/'Support Calculation'!$DL13,'Data- Refined'!$M13) -> 19 | O40: =IFERROR('Data- Refined'!$N13/'Support Calculation'!$DU13,'Data- Refined'!$N13) -> 6.8333333 | P40: =IFERROR('Data- Refined'!$O13/'Support Calculation'!$ED13,'Data- Refined'!$O13) -> 0 | Q40: =IFERROR('Data- Refined'!$P13/'Support Calculation'!EM13,'Data- Refined'!$P13) -> 0 | R40: =IFERROR('Data- Refined'!$Q13/'Support Calculation'!EV13,'Data- Refined'!$Q13) -> 0 | T40: FL | U40: =IFERROR('Data- Refined'!$B13/'Support Calculation'!$Q13,IF('Data- Refined'!$B13=0,0,"NA")) -> 3.9 | V40: =IFERROR('Data- Refined'!$C13/'Support Calculation'!$Z13,IF('Data- Refined'!$C13=0,0,"NA")) -> 15.411765 | W40: =IFERROR('Data- Refined'!$D13/'Support Calculation'!$AI13,IF('Data- Refined'!$D13=0,0,"NA")) -> 12.5 | X40: =IFERROR('Data- Refined'!$E13/'Support Calculation'!$AR13,IF('Data- Refined'!$E13=0,0,"NA")) -> 9.3076923 | Y40: =IFERROR('Data- Refined'!$F13/'Support Calculation'!$BA13,IF('Data- Refined'!$F13=0,0,"NA")) -> 8.2142857 | Z40: =IFERROR('Data- Refined'!$G13/'Support Calculation'!$BJ13,IF('Data- Refined'!$G13=0,0,"NA")) -> 7.4 | AA40: =IFERROR('Data- Refined'!$H13/'Support Calculation'!$BS13,IF('Data- Refined'!$H13=0,0,"NA")) -> 11.222222 | AB40: =IFERROR('Data- Refined'!$I13/'Support Calculation'!$CB13,IF('Data- Refined'!$I13=0,0,"NA")) -> 8.9473684 | AC40: =IFERROR('Data- Refined'!$J13/'Support Calculation'!$CK13,IF('Data- Refined'!$J13=0,0,"NA")) -> 7.4 | AD40: =IFERROR('Data- Refined'!$K13/'Support Calculation'!$CT13,IF('Data- Refined'!$K13=0,0,"NA")) -> 6.7647059 | AE40: =IFERROR('Data- Refined'!$L13/'Support Calculation'!$DC13,IF('Data- Refined'!$L13=0,0,"NA")) -> 8.1111111 | AF40: =IFERROR('Data- Refined'!$M13/'Support Calculation'!$DL13,IF('Data- Refined'!$M13=0,0,"NA")) -> 19 | AG40: =IFERROR('Data- Refined'!$N13/'Support Calculation'!$DU13,IF('Data- Refined'!$N13=0,0,"NA")) -> 6.8333333 | AH40: =IFERROR('Data- Refined'!$O13/'Support Calculation'!$ED13,IF('Data- Refined'!$O13=0,0,"NA")) -> 0 | AI40: =IFERROR('Data- Refined'!$P13/'Support Calculation'!EM13,IF('Data- Refined'!$P13=0,0,"NA")) -> 0 | AJ40: =IFERROR('Data- Refined'!$Q13/'Support Calculation'!EV13,IF('Data- Refined'!$Q13=0,0,"NA")) -> 0
B41: GA | C41: =IFERROR('Data- Refined'!$B14/'Support Calculation'!$Q14,'Data- Refined'!$B14) -> 2.5 | D41: =IFERROR('Data- Refined'!$C14/'Support Calculation'!$Z14,'Data- Refined'!$C14) -> 14.444444 | E41: =IFERROR('Data- Refined'!$D14/'Support Calculation'!$AI14,'Data- Refined'!$D14) -> 9.1428571 | F41: =IFERROR('Data- Refined'!$E14/'Support Calculation'!$AR14,'Data- Refined'!$E14) -> 13.272727 | G41: =IFERROR('Data- Refined'!$F14/'Support Calculation'!$BA14,'Data- Refined'!$F14) -> 5.9583333 | H41: =IFERROR('Data- Refined'!$G14/'Support Calculation'!$BJ14,'Data- Refined'!$G14) -> 6.2631579 | I41: =IFERROR('Data- Refined'!$H14/'Support Calculation'!$BS14,'Data- Refined'!$H14) -> 7.0714286 | J41: =IFERROR('Data- Refined'!$I14/'Support Calculation'!$CB14,'Data- Refined'!$I14) -> 9.5 | K41: =IFERROR('Data- Refined'!$J14/'Support Calculation'!$CK14,'Data- Refined'!$J14) -> 4.2142857 | L41: =IFERROR('Data- Refined'!$K14/'Support Calculation'!$CT14,'Data- Refined'!$K14) -> 5.8888889 | M41: =IFERROR('Data- Refined'!$L14/'Support Calculation'!$DC14,'Data- Refined'!$L14) -> 4.375 | N41: =IFERROR('Data- Refined'!$M14/'Support Calculation'!$DL14,'Data- Refined'!$M14) -> 8.375 | O41: =IFERROR('Data- Refined'!$N14/'Support Calculation'!$DU14,'Data- Refined'!$N14) -> 4.2142857 | P41: =IFERROR('Data- Refined'!$O14/'Support Calculation'!$ED14,'Data- Refined'!$O14) -> 0 | Q41: =IFERROR('Data- Refined'!$P14/'Support Calculation'!EM14,'Data- Refined'!$P14) -> 0 | R41: =IFERROR('Data- Refined'!$Q14/'Support Calculation'!EV14,'Data- Refined'!$Q14) -> 0 | T41: GA | U41: =IFERROR('Data- Refined'!$B14/'Support Calculation'!$Q14,IF('Data- Refined'!$B14=0,0,"NA")) -> 2.5 | V41: =IFERROR('Data- Refined'!$C14/'Support Calculation'!$Z14,IF('Data- Refined'!$C14=0,0,"NA")) -> 14.444444 | W41: =IFERROR('Data- Refined'!$D14/'Support Calculation'!$AI14,IF('Data- Refined'!$D14=0,0,"NA")) -> 9.1428571 | X41: =IFERROR('Data- Refined'!$E14/'Support Calculation'!$AR14,IF('Data- Refined'!$E14=0,0,"NA")) -> 13.272727 | Y41: =IFERROR('Data- Refined'!$F14/'Support Calculation'!$BA14,IF('Data- Refined'!$F14=0,0,"NA")) -> 5.9583333 | Z41: =IFERROR('Data- Refined'!$G14/'Support Calculation'!$BJ14,IF('Data- Refined'!$G14=0,0,"NA")) -> 6.2631579 | AA41: =IFERROR('Data- Refined'!$H14/'Support Calculation'!$BS14,IF('Data- Refined'!$H14=0,0,"NA")) -> 7.0714286 | AB41: =IFERROR('Data- Refined'!$I14/'Support Calculation'!$CB14,IF('Data- Refined'!$I14=0,0,"NA")) -> 9.5 | AC41: =IFERROR('Data- Refined'!$J14/'Support Calculation'!$CK14,IF('Data- Refined'!$J14=0,0,"NA")) -> 4.2142857 | AD41: =IFERROR('Data- Refined'!$K14/'Support Calculation'!$CT14,IF('Data- Refined'!$K14=0,0,"NA")) -> 5.8888889 | AE41: =IFERROR('Data- Refined'!$L14/'Support Calculation'!$DC14,IF('Data- Refined'!$L14=0,0,"NA")) -> 4.375 | AF41: =IFERROR('Data- Refined'!$M14/'Support Calculation'!$DL14,IF('Data- Refined'!$M14=0,0,"NA")) -> 8.375 | AG41: =IFERROR('Data- Refined'!$N14/'Support Calculation'!$DU14,IF('Data- Refined'!$N14=0,0,"NA")) -> 4.2142857 | AH41: =IFERROR('Data- Refined'!$O14/'Support Calculation'!$ED14,IF('Data- Refined'!$O14=0,0,"NA")) -> 0 | AI41: =IFERROR('Data- Refined'!$P14/'Support Calculation'!EM14,IF('Data- Refined'!$P14=0,0,"NA")) -> 0 | AJ41: =IFERROR('Data- Refined'!$Q14/'Support Calculation'!EV14,IF('Data- Refined'!$Q14=0,0,"NA")) -> 0
B42: HI | C42: =IFERROR('Data- Refined'!$B15/'Support Calculation'!$Q15,'Data- Refined'!$B15) -> 0 | D42: =IFERROR('Data- Refined'!$C15/'Support Calculation'!$Z15,'Data- Refined'!$C15) -> 2.1111111 | E42: =IFERROR('Data- Refined'!$D15/'Support Calculation'!$AI15,'Data- Refined'!$D15) -> 2 | F42: =IFERROR('Data- Refined'!$E15/'Support Calculation'!$AR15,'Data- Refined'!$E15) -> 1 | G42: =IFERROR('Data- Refined'!$F15/'Support Calculation'!$BA15,'Data- Refined'!$F15) -> 1.2 | H42: =IFERROR('Data- Refined'!$G15/'Support Calculation'!$BJ15,'Data- Refined'!$G15) -> 1.1666667 | I42: =IFERROR('Data- Refined'!$H15/'Support Calculation'!$BS15,'Data- Refined'!$H15) -> 1.7142857 | J42: =IFERROR('Data- Refined'!$I15/'Support Calculation'!$CB15,'Data- Refined'!$I15) -> 6 | K42: =IFERROR('Data- Refined'!$J15/'Support Calculation'!$CK15,'Data- Refined'!$J15) -> 1.1428571 | L42: =IFERROR('Data- Refined'!$K15/'Support Calculation'!$CT15,'Data- Refined'!$K15) -> 0.88888889 | M42: =IFERROR('Data- Refined'!$L15/'Support Calculation'!$DC15,'Data- Refined'!$L15) -> 1.6 | N42: =IFERROR('Data- Refined'!$M15/'Support Calculation'!$DL15,'Data- Refined'!$M15) -> 4.6 | O42: =IFERROR('Data- Refined'!$N15/'Support Calculation'!$DU15,'Data- Refined'!$N15) -> 4.8571429 | P42: =IFERROR('Data- Refined'!$O15/'Support Calculation'!$ED15,'Data- Refined'!$O15) -> 2.875 | Q42: =IFERROR('Data- Refined'!$P15/'Support Calculation'!EM15,'Data- Refined'!$P15) -> 0 | R42: =IFERROR('Data- Refined'!$Q15/'Support Calculation'!EV15,'Data- Refined'!$Q15) -> 0 | T42: HI | U42: =IFERROR('Data- Refined'!$B15/'Support Calculation'!$Q15,IF('Data- Refined'!$B15=0,0,"NA")) -> 0 | V42: =IFERROR('Data- Refined'!$C15/'Support Calculation'!$Z15,IF('Data- Refined'!$C15=0,0,"NA")) -> 2.1111111 | W42: =IFERROR('Data- Refined'!$D15/'Support Calculation'!$AI15,IF('Data- Refined'!$D15=0,0,"NA")) -> 2 | X42: =IFERROR('Data- Refined'!$E15/'Support Calculation'!$AR15,IF('Data- Refined'!$E15=0,0,"NA")) -> 1 | Y42: =IFERROR('Data- Refined'!$F15/'Support Calculation'!$BA15,IF('Data- Refined'!$F15=0,0,"NA")) -> 1.2 | Z42: =IFERROR('Data- Refined'!$G15/'Support Calculation'!$BJ15,IF('Data- Refined'!$G15=0,0,"NA")) -> 1.1666667 | AA42: =IFERROR('Data- Refined'!$H15/'Support Calculation'!$BS15,IF('Data- Refined'!$H15=0,0,"NA")) -> 1.7142857 | AB42: =IFERROR('Data- Refined'!$I15/'Support Calculation'!$CB15,IF('Data- Refined'!$I15=0,0,"NA")) -> 6 | AC42: =IFERROR('Data- Refined'!$J15/'Support Calculation'!$CK15,IF('Data- Refined'!$J15=0,0,"NA")) -> 1.1428571 | AD42: =IFERROR('Data- Refined'!$K15/'Support Calculation'!$CT15,IF('Data- Refined'!$K15=0,0,"NA")) -> 0.88888889 | AE42: =IFERROR('Data- Refined'!$L15/'Support Calculation'!$DC15,IF('Data- Refined'!$L15=0,0,"NA")) -> 1.6 | AF42: =IFERROR('Data- Refined'!$M15/'Support Calculation'!$DL15,IF('Data- Refined'!$M15=0,0,"NA")) -> 4.6 | AG42: =IFERROR('Data- Refined'!$N15/'Support Calculation'!$DU15,IF('Data- Refined'!$N15=0,0,"NA")) -> 4.8571429 | AH42: =IFERROR('Data- Refined'!$O15/'Support Calculation'!$ED15,IF('Data- Refined'!$O15=0,0,"NA")) -> 2.875 | AI42: =IFERROR('Data- Refined'!$P15/'Support Calculation'!EM15,IF('Data- Refined'!$P15=0,0,"NA")) -> 0 | AJ42: =IFERROR('Data- Refined'!$Q15/'Support Calculation'!EV15,IF('Data- Refined'!$Q15=0,0,"NA")) -> 0
... B82: WY | C82: =IFERROR('Data- Refined'!$B55/'Support Calculation'!$Q55,'Data- Refined'!$B55) -> 0 | D82: =IFERROR('Data- Refined'!$C55/'Support Calculation'!$Z55,'Data- Refined'!$C55) -> 0 | E82: =IFERROR('Data- Refined'!$D55/'Support Calculation'!$AI55,'Data- Refined'!$D55) -> 4.5 | F82: =IFERROR('Data- Refined'!$E55/'Support Calculation'!$AR55,'Data- Refined'!$E55) -> 2.8333333 | G82: =IFERROR('Data- Refined'!$F55/'Support Calculation'!$BA55,'Data- Refined'!$F55) -> 3.2 | H82: =IFERROR('Data- Refined'!$G55/'Support Calculation'!$BJ55,'Data- Refined'!$G55) -> 2 | I82: =IFERROR('Data- Refined'!$H55/'Support Calculation'!$BS55,'Data- Refined'!$H55) -> 10 | J82: =IFERROR('Data- Refined'!$I55/'Support Calculation'!$CB55,'Data- Refined'!$I55) -> 5.5 | K82: =IFERROR('Data- Refined'!$J55/'Support Calculation'!$CK55,'Data- Refined'!$J55) -> 2.25 | L82: =IFERROR('Data- Refined'!$K55/'Support Calculation'!$CT55,'Data- Refined'!$K55) -> 1 | M82: =IFERROR('Data- Refined'!$L55/'Support Calculation'!$DC55,'Data- Refined'!$L55) -> 1 | N82: =IFERROR('Data- Refined'!$M55/'Support Calculation'!$DL55,'Data- Refined'!$M55) -> 6 | O82: =IFERROR('Data- Refined'!$N55/'Support Calculation'!$DU55,'Data- Refined'!$N55) -> 6 | P82: =IFERROR('Data- Refined'!$O55/'Support Calculation'!$ED55,'Data- Refined'!$O55) -> 10 | Q82: =IFERROR('Data- Refined'!$P55/'Support Calculation'!EM55,'Data- Refined'!$P55) -> 7 | R82: =IFERROR('Data- Refined'!$Q55/'Support Calculation'!EV55,'Data- Refined'!$Q55) -> 0 | T82: WY | U82: =IFERROR('Data- Refined'!$B55/'Support Calculation'!$Q55,IF('Data- Refined'!$B55=0,0,"NA")) -> 0 | V82: =IFERROR('Data- Refined'!$C55/'Support Calculation'!$Z55,IF('Data- Refined'!$C55=0,0,"NA")) -> 0 | W82: =IFERROR('Data- Refined'!$D55/'Support Calculation'!$AI55,IF('Data- Refined'!$D55=0,0,"NA")) -> 4.5 | X82: =IFERROR('Data- Refined'!$E55/'Support Calculation'!$AR55,IF('Data- Refined'!$E55=0,0,"NA")) -> 2.8333333 | Y82: =IFERROR('Data- Refined'!$F55/'Support Calculation'!$BA55,IF('Data- Refined'!$F55=0,0,"NA")) -> 3.2 | Z82: =IFERROR('Data- Refined'!$G55/'Support Calculation'!$BJ55,IF('Data- Refined'!$G55=0,0,"NA")) -> 2 | AA82: =IFERROR('Data- Refined'!$H55/'Support Calculation'!$BS55,IF('Data- Refined'!$H55=0,0,"NA")) -> 10 | AB82: =IFERROR('Data- Refined'!$I55/'Support Calculation'!$CB55,IF('Data- Refined'!$I55=0,0,"NA")) -> 5.5 | AC82: =IFERROR('Data- Refined'!$J55/'Support Calculation'!$CK55,IF('Data- Refined'!$J55=0,0,"NA")) -> 2.25 | AD82: =IFERROR('Data- Refined'!$K55/'Support Calculation'!$CT55,IF('Data- Refined'!$K55=0,0,"NA")) -> 1 | AE82: =IFERROR('Data- Refined'!$L55/'Support Calculation'!$DC55,IF('Data- Refined'!$L55=0,0,"NA")) -> 1 | AF82: =IFERROR('Data- Refined'!$M55/'Support Calculation'!$DL55,IF('Data- Refined'!$M55=0,0,"NA")) -> NA | AG82: =IFERROR('Data- Refined'!$N55/'Support Calculation'!$DU55,IF('Data- Refined'!$N55=0,0,"NA")) -> 6 | AH82: =IFERROR('Data- Refined'!$O55/'Support Calculation'!$ED55,IF('Data- Refined'!$O55=0,0,"NA")) -> 10 | AI82: =IFERROR('Data- Refined'!$P55/'Support Calculation'!EM55,IF('Data- Refined'!$P55=0,0,"NA")) -> 7 | AJ82: =IFERROR('Data- Refined'!$Q55/'Support Calculation'!EV55,IF('Data- Refined'!$Q55=0,0,"NA")) -> 0
X218: NA

Sheet  Metrics Calculation
A1: Team Metrics
B3: Team Howard | C3: Team Smithers | D3: Elite | E3: Franchise | F3: Market Makers | G3: The Commissioners | O3: Number of working days | P3: ='Model Setup'!B3 -> 20
A4: # of agents | B4: ='Data- Refined'!AD4 -> 32 | C4: ='Data- Refined'!AE4 -> 30 | D4: ='Data- Refined'!AF4 -> 20 | E4: ='Data- Refined'!AG4 -> 18 | F4: ='Data- Refined'!AH4 -> 16 | G4: ='Data- Refined'!AI4 -> 18
A5: #leads/MB/Day | B5: =SUMPRODUCT('Optimization Model'!C5:C20,' Metrics Calculation'!$L$13:$L$28) -> 14.240438 | C5: =SUMPRODUCT('Optimization Model'!D5:D20,' Metrics Calculation'!$L$13:$L$28) -> 15.73125 | D5: =SUMPRODUCT('Optimization Model'!E5:E20,' Metrics Calculation'!$L$13:$L$28) -> 13.983465 | E5: =SUMPRODUCT('Optimization Model'!F5:F20,' Metrics Calculation'!$L$13:$L$28) -> 13.369325 | F5: =SUMPRODUCT('Optimization Model'!G5:G20,' Metrics Calculation'!$L$13:$L$28) -> 13.748039 | G5: =SUMPRODUCT('Optimization Model'!H5:H20,' Metrics Calculation'!$L$13:$L$28) -> 13.671262
A9: Hourly Lead Metrics | O9: Graphing Totals
B11: East | D11: West | H11: Totals Agents/hr | J11: Total Leads/Period | K11: Leads/Period/Agent | L11: Approx Leads/MB
B12: Team Howard | C12: Team Smithers | D12: Elite | E12: Franchise | F12: Market Makers | G12: The Commissioners | I12: Total Licenses/Hr | P12: 12 am to 1 am | Q12: 1 am to 2 am | R12: 2 am to 3 am | S12: 3am to 4 am | T12: 4 am to 5 am | U12: ='Data- Extract'!CJ3 -> 5 am to 6 am | V12: ='Data- Extract'!CK3 -> 6am to 7am | W12: ='Data- Extract'!CL3 -> 7 am to 8 am | X12: ='Data- Extract'!CM3 -> 8 am to 9 am | Y12: ='Data- Extract'!CN3 -> 9am to 10 am | Z12: ='Data- Extract'!CO3 -> 10 am to 11 am | AA12: ='Data- Extract'!CP3 -> 11 am to 12 pm | AB12: ='Data- Extract'!CQ3 -> 12 pm to 1 pm | ... AH12: ='Data- Extract'!CW3 -> 6 pm to 7 pm | AI12: 7pm to 8pm | AJ12: 8 pm to 9 pm | AK12: 9 pm to 10 pm | AL12: 10 pm to 11 pm | AM12: 11pm to 12 am
A13: ='Optimization Model'!B5 -> 5 am to 6 am | B13: ='Optimization Model'!C5*' Metrics Calculation'!B$4 -> 32 | C13: ='Optimization Model'!D5*' Metrics Calculation'!C$4 -> 0 | D13: ='Optimization Model'!E5*' Metrics Calculation'!D$4 -> 0 | E13: ='Optimization Model'!F5*' Metrics Calculation'!E$4 -> 0 | F13: ='Optimization Model'!G5*' Metrics Calculation'!F$4 -> 0 | G13: ='Optimization Model'!H5*' Metrics Calculation'!G$4 -> 0 | H13: =SUM(B13:G13) -> 32 | I13: =SUMIF(B13:G13,">0",'Data- Refined'!$U$56:$Z$56) -> 456 | J13: ='Data- Refined'!B56 -> 521 | K13: =J13/H13 -> 16.28125 | L13: =K13/$P$3 -> 0.8140625 | M13: 5 | O13: Original Lead Flow | P13: ='Data- Extract'!B57 -> 175 | Q13: ='Data- Extract'!C57 -> 145 | R13: ='Data- Extract'!D57 -> 148 | S13: ='Data- Extract'!E57 -> 257 | T13: ='Data- Extract'!F57 -> 426 | U13: ='Data- Extract'!G57 -> 782 | V13: ='Data- Extract'!H57 -> 3508 | W13: ='Data- Extract'!I57 -> 3851 | ... AM13: ='Data- Extract'!Y57 -> 218
A14: ='Optimization Model'!B6 -> 6am to 7am | B14: ='Optimization Model'!C6*' Metrics Calculation'!B$4 -> 0 | C14: ='Optimization Model'!D6*' Metrics Calculation'!C$4 -> 30 | D14: ='Optimization Model'!E6*' Metrics Calculation'!D$4 -> 0 | E14: ='Optimization Model'!F6*' Metrics Calculation'!E$4 -> 0 | F14: ='Optimization Model'!G6*' Metrics Calculation'!F$4 -> 0 | G14: ='Optimization Model'!H6*' Metrics Calculation'!G$4 -> 0 | H14: =SUM(B14:G14) -> 30 | I14: =SUMIF(B14:G14,">0",'Data- Refined'!$U$56:$Z$56) -> 456 | J14: ='Data- Refined'!C56 -> 2347 | K14: =J14/H14 -> 78.233333 | L14: =K14/$P$3 -> 3.9116667 | M14: 6 | O14: Floor - Adjusted Lead Flow | U14: ='Data- Extract'!CJ57 -> 526 | V14: ='Data- Extract'!CK57 -> 2353 | W14: ='Data- Extract'!CL57 -> 3390 | X14: ='Data- Extract'!CM57 -> 4371 | Y14: ='Data- Extract'!CN57 -> 4401 | Z14: ='Data- Extract'!CO57 -> 4029 | AA14: ='Data- Extract'!CP57 -> 3191 | AB14: ='Data- Extract'!CQ57 -> 2648 | ... AJ14: ='Data- Extract'!CY57 -> 612
